Workbook
Name aaaa: 'جدول کلی مددجوها'!$1:$1048576
Name aaaq: 'جدول کلی مددجوها'!$B$3:$H$7
Name etela: '[1] اطلاعات ورودد مددجو'!$1:$30
Name etela: '[2] اطلاعات ورودد مددجو'!$1:$30
Name etela: ' اطلاعات ورودد مددجو'!$1:$30
Name kamel: ' اطلاعات ورودد مددجو'!$1:$1048576
Name kha: 'لیست واریزی کل خیرین'!$B:$E
Name kj: ' اطلاعات ورودد مددجو'!$B$1
Name kj: #REF!
Name kj: #REF!
Name kj: #REF!
Name kj: #REF!
Name kod: '[3]2'!$J$5
Name koli: 'جدول کلی مددجوها'!$B:$AZ
Name list: 'لیست واریزی کل خیرین'!$D:$E
Name madad: #REF!
Name madad: #REF!
Name madad: #REF!
Name madad: #REF!
Name mah: '[1]لیست واریزی ماهیانه'!$Q$2:$R$13
Name mah: '[2]لیست واریزی ماهیانه'!$Q$2:$R$13
Name mah: 'لیست واریزی ماهیانه'!$Q$2:$R$13
Name nam: 'خلاصه هزینه کرد مددجوها'!$B:$D
Name nam: #REF!
Name qq: '[1]گزارش رداخت خیرین'!$T$1
Name qq: '[2]گزارش رداخت خیرین'!$T$1
Name qq: #REF!
Name ta: 'ریزهزینه کرد مددجوها'!$T$1:$U$12
Name ta: #REF!
Name varizi: 'لیست واریزی کل خیرین'!$J$3:$U$80
Name varizi: '[1]لیست واریزی کل خیرین'!$G$3:$R$93
Name varizi: '[2]لیست واریزی کل خیرین'!$G$3:$R$80
Name varizi: 'لیست واریزی کل خیرین'!$J$3:$U$142

Sheet جدول کلی مددجوها
B1: 1 | C1: 2 | D1: 3 | E1: 4 | F1: 5 | G1: 6 | H1: 7 | I1: 8 | J1: 9 | K1: 10 | L1: 11 | M1: 12 | N1: 13 | O1: 13 | P1: 14 | Q1: 15 | R1: 16 | S1: 17 | T1: 18 | U1: 19 | V1: 20 | W1: 21
A2: ردیف | B2: کد مددجو | C2: نام | D2: نام خانوادگی | E2: نام پدر | F2: نام مادر | G2: تاریخ تولد | H2: کد ملی | I2: محل تولد | J2: پایه تحصیلی | K2: رشته | L2: مدرسه | M2: آدرس | N2: شماره تلفن | O2: شماره تلفن ولی | P2: کتاب کمک درسی/غیردرسی | Q2: کلاس کنکور | R2: مشاور تحصیلی | S2: معلم خصوصی | T2: خدمات درمانی | V2: توضیحات | W2: آدرس مدرسه
A3: 1 | B3: 1 | C3: ریحانه | D3: نوری شفیق | E3: عبدالحکیم | F3: لیلی ظهوریان شفیق | G3: 1385/05/06 | H3: 0928177246 | I3: مشهد | J3: یازدهم | K3: ریاضی | L3: حضرت خدیجه | M3: رسالت 136- خیابان امام خمینی- امام خمینی 2- پلاک 36 | N3: 09381233298/ 09398771647 خواهر | O3: 09381233298/ 09398771647 خواهر | P3: سه عدد کتاب اقتصاد و فلسفه(شهر کتاب)-تست فیزیک ریاضیات آمارواحتمال(جزوه)-شیمی-جزوه حرکت شناسی-جزوه هندسه-جزوه فیزیک(الکتریسیته جاری)-عربی-فیزیک-حسابان1 | Q3: ــــــــــــــ | R3: خانم قوامی | S3: ــــــــــــــ | T3: ــــــــــــــ | V3: نیاز شدید به مشاوره دارد و در حال حاضر همکاری نمی کند.
A4: 2 | B4: 2 | C4: ریحانه | D4: طراقی فرد | E4: علی اکبر | F4: سکینه رنجبر | G4: 1386/05/13 | H4: 0928744272 | I4: مشهد | J4: دهم | K4: علوم انسانی | L4: حضرت خدیجه | M4: رسالت 136-خیابان امام خمینی21-شهریار 4 پلاک 27 | N4: 09392569929 09025734904 مادر | O4: 09392569929 09025734904 مادر | P4: دروس طلایی*- منطق10* -ریاضی1 منودرسام*- عربی* - اقتصاد- اقتصاد*- جامعه*- منطق10*- ریاضی-فنون دهم- منطق*- | R4: خانم قوامی | V4: علاقمند به رشته دبیری است
A5: 3 | B5: 3 | C5: زهرا | D5: قهستانی | E5: مجتبی | F5: نرگس قوی | G5: 1386/01/04 | H5: 0928539733 | I5: مشهد | J5: دهم | K5: ریاضی | L5: حضرت خدیجه | M5: رسالت 138-امام خمینی 3-رخش بهار 8-پلاک 37 | N5: 09373250328 09363307472 پ 09360772378 م | O5: 09373250328 09363307472 پ 09360772378 م | P5: دروس طلایی تجربی*-منو درسام(انگلیسی)* | R5: خانم قوامی | V5: علاقمند به تحصیل در دانشگاه فرهنگیان
A6: 4 | B6: 4 | C6: مهلا | D6: قهستانی | E6: حسین | F6: فاطمه ابراهیم پور | G6: 1386/05/30 | H6: 0928779262 | I6: مشهد | J6: دهم | K6: تجربی | L6: حضرت خدیجه | M6: رسالت 136-امام خمینی 12-پلاک 6 | N6: 09228665372 09357415452 پ 09302849676 م | O6: 09228665372 09357415452 پ 09302849676 م | P6: دروس طلایی تجربی*-منو درسام(انگلیسی)* | R6: خانم قوامی | V6: علاقمند به رشته پزشکی
A7: 5 | B7: 5 | C7: رقیه | D7: رضاپور | E7: محمد رضا | F7: بسته گل احمدی | G7: 1386/01/18 | H7: 0671175866 | I7: بجنورد | J7: دهم | K7: تجربی | L7: حضرت خدیجه | M7: رسالت 134-خیابان شهید غلامی-کنار مسجد سید الشهدا | N7: 09929983735 09017614576 م 09157171782 م 09333752599 پ | O7: 09929983735 09017614576 م 09157171782 م 09333752599 پ | P7: دروس طلایی تجربی*-منو درسام(انگلیسی)* | R7: خانم قوامی | V7: علاقمند به رشته پزشکی
A8: 6 | B8: 6 | C8: راضیه | D8: رضاپور | E8: محمد رضا | F8: بسته گل احمدی | G8: 1386/01/18 | H8: 0671175841 | I8: بجنورد | J8: دهم | K8: ریاضی | L8: آرمیتا مصلی نژاد | M8: رسالت 134-خیابان شهید غلامی-کنار مسجد سید الشهدا | N8: 09157171782 09017614576 م 09333752599 پ | O8: 09157171782 09017614576 م 09333752599 پ | V8: علاقمند به رشته مهندسی کامپیوتر
A9: 7 | B9: 7 | C9: ربابه | D9: رضاپور | E9: محمد رضا | F9: بسته گل احمدی | G9: 1386/01/18 | I9: بجنورد | J9: دهم | K9: انسانی | L9: حضرت خدیجه | M9: رسالت 134-خیابان شهید غلامی-کنار مسجد سید الشهدا | N9: 09929568872 09017614576 م 09333752599 پ | O9: 09929568872 09017614576 م 09333752599 پ | P9: منطق10* -ر یاضی1 (منو درسام)* - اقتصاد-جامعه*-منطق* | R9: خانم قوامی | V9: علاقمند به وکالت
A10: 8 | B10: 8 | C10: پریسا | D10: اعتماد منش | E10: محمد | F10: زهره عامری | G10: 1385/06/28 | H10: 0928280098 | I10: مشهد | J10: دوازدهم | K10: تجربی | L10: آرمیتا مصلی نزاد | M10: توس 33- شکری2-سه قطعه مانده به چهارراه اوت-سمت راست-طبقه 4 | N10: 09900785044 09035063996 پ | O10: 09900785044 09035063996 پ | P10: سلامت و بهداشت-سه سطحی زبان3-سه سطحی فارسی3 موج آزمون عربی-زبان انگلیسی جامع کنکور*-جزوه عربی-زیست شناسی جامع-جزوه فیزیک پایه(10و11)ریاضیات تجربی جامع-دروس طلایی(کلیه دروس) | V10: علاقمند به رشته پزشکی
A11: 9 | B11: 9 | C11: فاطمه | D11: موسوی | E11: میرحسین | G11: 1384/02/04 | H11: 091020180399 | I11: افغانستان | J11: دوازدهم | K11: تجربی | L11: حضرت خدیجه | M11: آخر خیابان رسالت-روستای قرقی سفلا-خیابان کشمیری 36-بعد از چهارراه اول-پلاک 39 | N11: 09378969874 م 09379706423 پ | O11: 09378969874 م 09379706423 پ | P11: عربی جامع*-زبان انگلیسی جامع کنکور*-شیمی3(کنکور99)-حسابان2تست فیزیک-ریاضیات گسسته-کتاب نوروز ریاضی ج1-فیزیک پایه(10و11)فیزیک3(12)- جزوه زیست شناسی-زیست شناسی و آزمایشگاه2-زیست شناسی جامع-شیمی پایه(10و11)ریاضیات جامع- | R11: خانم قوامی | V11: علاقمند به رشته پزشکی(متخصص مغز و اعصاب)
A12: 10 | B12: 10 | C12: مریم | D12: رحمانی | E12: نعمت الله | F12: طاهره شاه نقی | G12: 1383/09/14 | H12: 0928335204 | I12: مشهد | J12: دوازدهم | K12: ریاضی | L12: حضرت خدیجه | M12: رسالت 120-رجایی 6- پلاک 45(داخل میلان-کنار مدرسه غیرانتفاعی پسرانه-زنگ سوم | N12: 09380617293 09057403341 م 09397976616 پ | O12: 09380617293 09057403341 م 09397976616 پ | P12: مجموعه کتابهای عطارد(دستور زبان فارسی)-جزوه عربی سه سطحی شیمی پایه-3سطحی فیزیک-3سطحی ریاضیات گسسته و آمار-3سطحی هندسه-فیزیک دوازدهم(بانک تست)هندسه جامع-جامع ریاضیات گسسته و احتمال-جزوه آمارواحتمال-جزوه هندسه3-جزوه کنکور هندسه(10و11)-حسابان وریاضیات پایه ج1و2-موج آزمون هندسه-موج آزمون ریاضی-موج آزمون ریاضیات گسسته و..-شیمی جامع-فیزیک موج آزمون | R12: خانم قوامی | V12: کتابهای کمک آموزشی لازم دارد
A13: 11 | B13: 11 | C13: ناهید | D13: کمالی گروی | E13: حسین | F13: زینب مهربان رزگی | G13: 1385/09/18 | H13: 0928394174 | I13: مشهد | J13: دهم | K13: ریاضی | L13: حضرت خدیجه | M13: رسالت 130-غلامی 18-پلاک 21 | N13: 09059908418 09152067310 م 09908878616 پ | O13: 09059908418 09152067310 م 09908878616 پ | P13: واژگان ضروری انگلیسی-اقتصاد ویژه کنکور-علوم و فنون ادبی عربی*-جامعه*-منطق*- | R13: خانم قوامی
A14: 12 | B14: 12 | C14: الهام | D14: صمدی سعادت آباد | E14: هاشم | F14: فاطمه بخشی | G14: 1385/07/22 | H14: 0721083781 | I14: تربت جام | J14: دهم | K14: انسانی | L14: آرمیتا مصلی نژاد | M14: توس 97-الزهرای 10-چهل حجره 17- پلاک 38 | N14: 09150090658 09940117245 09156484356 م 09159095701 پ | O14: 09150090658 09940117245 09156484356 م 09159095701 پ | V14: با مادربزرگش زندگی میکند-مشکل گوش و چشم دارد-مادرش جدا شده است
A15: 13 | B15: 13 | C15: کوثر | D15: مولایی | E15: ستار | F15: فاطمه دارابی شلم زار | G15: 1383/12/14 | H15: 0927602172 | I15: تهران | J15: دوازدهم | K15: تجربی | L15: دبیرستان شاهد | M15: بلوار دوم طبرسی-طبرسی 4-نظام دوست 24-غفاری 30-پلاک 1-طبقه همکف | N15: 09053110021 09398957719 م | O15: 09053110021 09398957719 م | P15: دور دنیا در 4ساعت(کل دروس تجربی)-سلامت و بهداشت عربی جامع*-ادبیات جامع-حفظیات شیمی کنکور-دور دنیا در 4ساعت(12 دوره) زیست شناسی پایه(10و11)-شیمی جامع-زیست شناسی پایه دهم و یازدهم
A16: 14 | B16: 14 | C16: زهرا | D16: تاتاری | E16: مهدی | F16: آمنه قایمی | G16: 1385/02/06 | H16: 0025909738 | I16: تهران | J16: یازدهم | K16: تجربی | L16: دبیرستان نرجس (شهرستان زاوه- شهر دولت آباد) | M16: خراسان رضوی-شهرستان زاوه-قلعه حسن خان | N16: 09945192457 09908177165 م | O16: 09945192457 09908177165 م | P16: دروس طلایی-زیست | V16: معرف خانم سمیعی
A17: 15 | B17: 15 | C17: یگانه | D17: رجایی سمرا | E17: حسین | F17: فرزانه صدیقی (زبرخان) | G17: 1385/12/15 | H17: 0928551113 | I17: مشهد | J17: دهم | K17: تجربی | L17: رستگار مقدم | M17: توس 43-غلامی6-رادمرد 7-انتهای کوچه-سمت راست | N17: 09397686036 09353218951 م | O17: 09397686036 09353218951 م | V17: ناپدری نامرد-اختلافات شدید خانوادگی-معرف آقای نقیبی
A18: 16 | B18: 16 | C18: یگانه | D18: خردمند سنجد بوری | E18: سید حسین | F18: عصمت قربانی | G18: 1384/10/21 | H18: 0927912678 | I18: مشهد | J18: یازدهم | K18: تجربی | L18: رستگار مقدم | M18: حر13- کوچه 54-(سر درب منزل نوشته دعای کمیل) | N18: 09045235720 | O18: 09156286174 م | P18: فیزیک(سیرتاپیاز)-دروس طلایی | V18: افسردگی شدید-(از دخترهای آقای نقیبی هستند)
A19: 17 | B19: 17 | C19: کوثر | D19: فارقی | F19: زهرا مختاری | H19: 0928729826 | J19: دهم | K19: انسانی | L19: رستگار مقدم | M19: بابانظر 18-حسینی محراب 93-خادمی 6 پلاک 160 (پنجتن 3-سلمان 6-پلاک 160) | N19: 09305985342 09360554032 خواهر 09300610960 م 09305985396 | O19: 09305985342 09360554032 خواهر 09300610960 م 09305985396 | V19: دو گربه
A20: 18 | B20: 18 | C20: ریحانه | D20: نجفی | E20: احمد | G20: 1385/11/02 | H20: 0950047384 | I20: مشهد | J20: دهم | K20: تجربی | L20: رستگار مقدم | M20: شهرک شهید رجایی-حر 54/24- پلاک 108- طبقه دوم | N20: 09152548041 09352584850 09156019826 خواهر | O20: 09152548041 09352584850 09156019826 خواهر | V20: سرخس بوده-پدر و مادر فوت کردن-شوهر خواهر در زندان-شرایط بسیار بدب دارد-از دادگاه حکم رشد گرفته است | W20: اروند 21
A21: 19 | B21: 19 | C21: نادیا | D21: احمدی | E21: عبدالرحمن | F21: رحیمه احمدی | G21: 1383/01/15 | H21: P03085763 | I21: هرات | J21: دوازدهم | K21: ریاضی | L21: حضرت خدیجه | M21: جاده سیمان-رسالت 136-امام خمینی 21-شهریار 2- پلاک 26 | N21: 09159230957 م 09306154558 پ | O21: 09159230957 م 09306154558 پ | V21: در طراحی و گرافیک بسیار بااستعداد-مشکل شنوایی دارد و نیاز به سمعک دارد-از نظر مکالمه و صحبت کردن مشکل دارد-علاقمند به کامپیوتر-برنامه نویس-طراحی پوستر و اینفو گرافی
A22: 20 | B22: 20 | C22: پری | D22: زارع | E22: غلامعلی | F22: شهناز دلدار | G22: 1384/09/09 | H22: 0820611743 | I22: شیروان | J22: دهم | K22: تجربی | L22: رستگار مقدم | N22: 09915317983 09352523868 م | O22: 09915317983 09352523868 م
A23: 21 | B23: 21 | C23: ملیکا | D23: نماز | E23: جواد | F23: مرجان عمرانی | G23: 1395/03/29 | H23: 6500294351 | I23: تربت حیدریه | J23: اول دبستان | L23: دبستان بعثت | M23: نخریسی-احزاب 9- پتاک 405 (چهارراه مقدم-پروین اعتصامی 8-سلیمانیمنش 10-پلاک 405) | N23: 09159140096 م 09945583303 م | O23: 09159140096 م 09945583303 م | V23: معرف مسعود خازنی
A24: 22 | B24: 22 | C24: مهدیار | D24: نماز | E24: جواد | F24: مرجان عمرانی | G24: 1390/09/24 | H24: 0970439210 | I24: مشهد | J24: پنجم دبستان | L24: دبستان بهادر زاده | M24: نخریسی-احزاب 9- پتاک 405 (چهارراه مقدم-پروین اعتصامی 8-سلیمانیمنش 10-پلاک 405) | N24: 09159140096 م 09945583303 م | O24: 09159140096 م 09945583303 م | V24: معرف مسعود خازنی پدر معتاد
A25: 23 | B25: 23 | C25: محمد رضا | D25: سروری | J25: پنجم دبستان | L25: دبستان بهادر زاده | M25: نخریسی -احزاب 4-پلاک 471 | N25: 09051762599 م | O25: 09051762599 م
A26: 24 | B26: 24 | C26: کمیل | D26: سروری | J26: سوم دبستان | L26: دبستان بهادر زاده | M26: نخریسی ا-حزاب 4-پلاک 471 | N26: 09051762599 م | O26: 09051762599 م
A27: 25 | B27: 25 | C27: مبینا | D27: عباسی | J27: یازدهم | K27: تجربی | L27: رستگار مقدم
A28: 26 | B28: 26 | C28: الناز | D28: حبیب زاده | E28: علی اکبر | G28: 1383/11/06 | H28: 0927429055 | J28: دوازدهم | K28: تجربی | L28: مصلی نزاد | M28: سه راه فردوسی-شاهنامه 35-شهید شعبانی 22 | N28: 09362939144 الناز و مادر 09353547499 پ | O28: 09362939144 الناز و مادر 09353547499 پ | V28: منزل نیمه کاره در روستا
A29: 27 | B29: 27 | C29: نرگس | D29: علی نژاد یادگار | E29: تیمور | G29: 1386/06/04 | H29: 0928807916 | I29: مشهد | J29: دهم | K29: تجربی | L29: مصلی نزاد | M29: توس 91-خالقی9-پلاک 47 | N29: 09376893476 09362616810 م | O29: 09376893476 09362616810 م | V29: نیاز به کلاسهای تقویتی دارد-علاقمند به پزشکی
A30: 28 | B30: 28 | C30: زینب | D30: ادبی یکه باغی | E30: شعبان | G30: 1384/12/27 | H30: 0770332455 | J30: یازدهم | K30: تجربی | L30: مصلی نزاد | M30: توس 159-قبل از جاده خاکی-سمت چپ | N30: 09932666021 09156920446 م | O30: 09932666021 09156920446 م | V30: علاقمکد به پزشکی-نیاز به مشاوره دارد-کتابهای خیلی سبز میخواند-علاقه به موسیقی و ورزش
A31: 29 | B31: 29 | C31: آتنا | D31: جر | E31: محمدرضا | G31: 1384/07/25 | H31: 0927858983 | J31: یازدهم | K31: تجربی | L31: مصلی نزاد | M31: توس 117-اسماعیل آباد-روبروی مدرسه جواد المه-پلاک 17 | N31: 09020882279 م 05136655064 مدرسه | O31: 09020882279 م 05136655064 مدرسه | V31: تحت پوشش بهزیستی
A32: 30 | B32: 30 | C32: مبینا | D32: علیزاده | N32: 09309861852 | O32: 09309861852
A33: 31 | B33: 31 | C33: یگانه | D33: محمد دوست | E33: یاور | F33: خیرالنسا | G33: 1385/12/22 | H33: 0928635236 | I33: مشهد | J33: دهم | K33: تجربی | L33: حضرت زینب | M33: شهرک شهید رجایی-روستای کنه بیست-تربیت 2 | N33: 09309935285 | O33: 09152364032
A34: 32 | B34: 32 | C34: رقیه | D34: الزوینی | E34: علی | G34: 1386/05/09 | H34: 9162124328 | M34: جاده سیمان-همت آباد-رسالت 129-خیابان طالقانی دو-کوچه قبل دبیرستان-شهید مطهری-(بوستان) یک-بمبست اول-پلاک 1 | N34: 09368865778 09156969665 پ 09156468517 م | O34: 09368865778 09156969665 پ 09156468517 م | V34: دانش آموز زرنگ-مهاجر عراقی
A35: 33 | B35: 33 | C35: عارفه | D35: آذرنگ | E35: مجتبی | F35: عفت | G35: 1386/04/09 | H35: 0928708411 | I35: مشهد | M35: جاده سیمان-رسالت 168-رسالت 168/9-پلاک 9 | N35: 09045886491 09358851503 پ | O35: 09045886491 09358851503 پ
A36: 34 | B36: 34 | C36: یگانه | D36: عبدالله زاده | N36: 09920748929 | O36: 09920748929
A37: 35 | B37: 35
A38: 36 | B38: 36
A39: 37 | B39: 37
V40: علاقمند به دندانپزشکی-جراح فک و دهان

Sheet  اطلاعات ورودد مددجو
B1: k1 | C1: m1 | D1: S | F1: کد مددجو | G1: 1 | H1: 2 | I1: 3 | J1: 4 | K1: 5 | L1: 6 | M1: 7 | N1: 8 | O1: 9 | P1: 10 | Q1: 11 | R1: 12 | S1: 13 | T1: 14 | U1: 15 | V1: 16 | W1: 17 | X1: 18 | Y1: 19 | Z1: 20 | AA1: 21 | AB1: 22 | AC1: 23 | AD1: 24 | AE1: 25 | AF1: 26 | AG1: 27 | AH1: 28 | AI1: 29 | AJ1: 30 | AK1: 31 | AL1: 32 | AM1: 33 | AN1: 34 | AO1: 35 | AP1: 36 | AQ1: 37 | AR1: 38 | AS1: 39 | AT1: 40 | AU1: 41 | AV1: 42 | AW1: 43 | AX1: 44 | AY1: 45 | AZ1: 46 | BA1: 47 | BB1: 48 | BC1: 49 | BD1: 50 | BE1: 51 | BF1: 52 | BG1: 53 | BH1: 54 | BI1: 55 | BJ1: 56 | BK1: 57
A2: 1 | B2: هزینه کلی موسسه | C2: هزینه کلی به مددجویان | D2: هزینه مربوط به تعمیرات مدارس از واریزی خانم عین علی | F2: نام و نام خانوادگی | G2: ریحانه نوری شفیق | H2: ریحانه طراقی فرد | I2: زهرا قهستانی | J2: مهلا قهستانی | K2: رقیه رضاپور | L2: راضیه رضاپور | M2: ربابه رضاپور | N2: پریسا اعتمادمنش | O2: فاطمه موسوی | P2: مریم رحمانی | Q2: ناهید کمالی گروی | R2: الهام صمدی | S2: کوثر مولایی | T2: زهرا تاتاری | U2: یگانه رجایی سمرا | V2: یگانه خرمند سنجدبوری | W2: کوثر فارقی | X2: ریحانه نجفی | Y2: نادیا احمدی | Z2: پری زارع | AA2: ملبکا نماز | AB2: مهدبار نماز | AC2: محمدرضا سروری | AD2: کمیل سروری | AE2: مبینا عباسی | AF2: الناز حبیب زاده | AG2: نرگس علینژاد | AH2: زینب ادبی یکه باغی | AI2: آتنا جر | AJ2: مبینا علیزاده | AK2: یگانه محمددوست | AL2: رقیه الزوینی | AM2: عارفه آذرنگ | AN2: یگانه عبدالله زاده | AO2: ثنا پور دوران | AP2: هدیه محمد پور جاغرق | AQ2: کوثر صفری | AR2: حانیه دشتبانی | AS2: فاطمه حیدرزاده | AT2: سیده شقایق محمودی زاده | AU2: مائده وفای فرخانی | AV2: فرزانه خوشگفتار | AW2: فرخنده خوشگفتار | AX2: ریحانه منفردی | AY2: احمد خاوری عدل | AZ2: صادق نجمی | BA2: امیرحسین محمدزاده | BB2: امیرحسین مودب | BC2: متین شاملی | BD2: امیر پارسا قویدل | BE2: محمدسجاد طوسی گروهی | BF2: امیرحسین بنا زاده | BG2: محمد امین تاتاری | BH2: فاطمه سادات سلطانی | BI2: سحر خادم حقیقی | BJ2: سارینا داوری | BK2: ثمین اکبری شاندیز
A3: 2 | E3: =G3 -> 1385/05/06 | F3: تاریخ تولد : | G3: 1385/05/06 | H3: 1386/05/13 | I3: 1386/01/04 | J3: 1386/05/30 | K3: 1386/01/18 | L3: 1386/01/18 | M3: 1386/01/18 | N3: 1385/06/28 | O3: 1384/02/04 | P3: 1383/09/14 | Q3: 1385/09/18 | R3: 1383/09/14 | T3: 1385/02/06 | U3: 1385/12/15 | V3: 1384/10/21 | X3: 1385/11/02 | Z3: 1384/09/09 | AA3: 1395/03/29 | AB3: 1390/09/24
A4: 3 | E4: =G4 -> 0 | F4: محل تولد | N4: مشهد | O4: افغانستان | P4: مشهد | Q4: مشهد | T4: تهران | U4: مشهد | V4: مشهد | X4: مشهد | Z4: شیروان | AA4: تربت حیدریه | AB4: مشهد
A5: 4 | E5: =G5 -> 0 | F5: محل صدور: | N5: مشهد | P5: مشهد | Q5: مشهد | T5: تهران | U5: مشهد | V5: مشهد | X5: مشهد | Z5: شیروان | AA5: تربت حیدریه | AB5: مشهد
A6: 5 | E6: =G6 -> عبدالحکیم | F6: نام پدر | G6: عبدالحکیم | H6: علی اکبر | I6: مجتبی | J6: حسین | K6: محمدرضا | L6: محمدرضا | M6: محمدرضا | N6: محمد | O6: میرحسین | P6: نعمت الله | Q6: حسین | T6: مهدی | U6: حسين | V6: سید حسين | X6: احمد | Z6: غلامعلی | AA6: جواد | AB6: جواد
A7: 6 | E7: =G7 -> 0 | F7: نام مادر | T7: آمنه قابمی | U7: فرزانه صدیقی | V7: عصمت قربانی | W7: زهرا مختاری | X7: - | Z7: - | AA7: مرجان عمرانی | AB7: مرجان عمرانی
A8: 7 | E8: =G8 -> دختر | F8: جنسیت | G8: دختر | H8: دختر | I8: دختر | J8: دختر | K8: دختر | L8: دختر | M8: دختر | N8: دختر | O8: دختر | P8: دختر | Q8: دختر | R8: دختر | S8: دختر | T8: دختر | U8: دختر | V8: دختر | W8: دختر | X8: دختر | Y8: دختر | Z8: دختر | AA8: دختر | AB8: دختر | AC8: پسر | AD8: پسر | AE8: دختر | AF8: دختر | AG8: دختر | AH8: دختر | AI8: دختر | AJ8: دختر | AK8: دختر | AL8: دختر | AM8: دختر | AN8: دختر | AO8: دختر | AP8: دختر | AQ8: دختر | AR8: دختر | AS8: دختر | AT8: دختر | AU8: دختر | AV8: دختر | AW8: دختر | AX8: دختر | AY8: پسر | AZ8: پسر | BA8: پسر | BB8: پسر | BC8: پسر | BD8: پسر | BE8: پسر | BF8: پسر | BG8: پسر | BH8: دختر | BI8: دختر | BJ8: دختر | BK8: دختر
A9: 8 | E9: =G9 -> 0 | F9: شماره ملی / شماره شناسنامه | H9: 928744272 | I9: 928539733 | J9: 928779262 | N9: 928280098 | O9: 91020180399 | P9: 0927335204- | Q9: 0928394174- | T9: 0025909738- | U9: 0928551113- | V9: 0927912678- | W9: 0928729826- | X9: 0950047384- | Y9: 0929731451- | Z9: 0820611743- | AA9: 6500294351 | AB9: 0970439210-
A10: 9 | E10: =G10 -> مدرسه حضرت خدیجه | F10: معرف | G10: مدرسه حضرت خدیجه | H10: مدرسه حضرت خدیجه | I10: مدرسه حضرت خدیجه | J10: مدرسه حضرت خدیجه | K10: مدرسه حضرت خدیجه | L10: مدرسه حضرت خدیجه | M10: مدرسه حضرت خدیجه | N10: مدرسه آرمیتا مصلی نژاد- ناحیه تباتکان | O10: مدرسه حضرت خدیجه | P10: مدرسه حضرت خدیجه | Q10: مدرسه حضرت خدیجه | R10: مدرسه آرمیتا مصلی نژاد- ناحیه تباتکان | S10: دبیرستان شاهد | T10: خانم سمییعی | U10: دبیرستان رستگارمقدم | V10: دبیرستان رستگارمقدم | W10: دبیرستان رستگارمقدم | X10: دبیرستان رستگارمقدم | Y10: دبیرستان خدیجه | Z10: دبیرستان رستگارمقدم | AA10: مسعود خازنی | AB10: مسعود خازنی | AC10: مسعود خازنی | AD10: مسعود خازنی | AE10: خانم اورلی | AF10: خانم توکلی | AG10: خانم ارمغان | AI10: خانم ارمغان
A11: 10 | E11: =G11 -> 0 | F11: تاریخ شروع خدمات
A12: 11 | E12: =G12 -> رسالت 136- خیابان امام خمینی- امام خمینی 2 پلاک 36 | F12: آدرس محل سکونت | G12: رسالت 136- خیابان امام خمینی- امام خمینی 2 پلاک 36 | H12: رسالت 136- خیابان امام خمینی- امام خمینی 21- شهریار 4- پلاک 27 | I12: رسالت 136- خیابان امام خمینی- امام خمینی 3- رخش بهار 8- پلاک 37 | J12: رسالت 136- خیابان امام خمینی- امام خمینی 12- پلاک 6 | K12: رسالت 134- خیابان شهید غلامی-کنار مسجد سیداشهدا | L12: رسالت 134- خیابان شهید غلامی-کنار مسجد سیداشهدا | M12: رسالت 134- خیابان شهید غلامی-کنار مسجد سیداشهدا | N12: توس 33- شکری 2- وسط کوچه- سمت راست- منزل نیمه کاره | O12: کشمیری 36- بعد از چهارراه اول پلاک 39 | P12: رسالت 120- رجایی 6- پلاک 45 | Q12: غلامی 18- پلاک 21 | R12: توس 97- الزهرا 10- ... 17- پلاک 38 | T12: تربت حیدریه - روستای قلعه حسن خان | U12: توس 43 - غلامی 6- رادمرد 7 - انتهای کوچه سمت راست | V12: حر 13- کوچه 54- سردرب منزل(دعای کمیل) | W12: پنجتن 3- سلمان 6- پلاک 43 | X12: حر 56 | Z12: رسالت 71 - درب قهوه ای - پلاک 23 | AA12: چهارراه مقدم - پروین اعتصامی 8- سلیمانی منش 10- پلاک 405 | AB12: چهارراه مقدم - پروین اعتصامی 8- سلیمانی منش 10- پلاک 405
A13: 12 | E13: =G13 -> 0 | F13: کد پستی محل سکونت :
A14: 13 | E14: =G14 -> خانم توکلی | F14: معرفی توسط : | G14: خانم توکلی | H14: خانم توکلی | I14: خانم توکلی | J14: خانم توکلی | K14: خانم توکلی | L14: خانم توکلی | M14: خانم توکلی | N14: خانم ارمغان | O14: خانم توکلی | P14: خانم توکلی | Q14: خانم توکلی | R14: خانم توکلی | S14: آقای نقیبی | T14: خانم سمییعی | U14: آقای نقیبی | V14: آقای نقیبی | W14: آقای نقیبی | X14: آقای نقیبی | Z14: آقای نقیبی | AA14: مسعود خازنی | AB14: مسعود خازنی | AC14: مسعود خازنی | AD14: مسعود خازنی
A15: 14 | E15: =G15 -> 0 | F15: پست الکترونیکی :
A16: 15 | E16: =G16 -> 9381233298 | F16: تلفن : | G16: 9381233298 | H16: 9392569929 | I16: 9373250328 | J16: 9228665372- 09357415452-09302849676 | K16: 9229983735- 09017614576-09157171782-09333752599 | L16: 9229983735- 09017614576-09157171782-09333752599 | M16: 9229983735- 09017614576-09157171782-09333752599 | N16: 9900785044 | O16: 03978969874- | P16: 09380617293-09397976616-09057403341 | Q16: 09152067310-09908878616 | R16: 09150090658-09156484356-09159095701 | S16: 09053110021-09398957719 | T16: 09945192457-0998177165 | U16: 09397686036-09353218951 | V16: 09046651101-09156286174 | W16: 09305985396-09360554032-09300610960 | X16: 09352584850-09156019826-09152548041 | Y16: 9156194069 | Z16: 09915317983-09352523868 | AA16: 09159140096-09945583303 | AB16: 09159140096-09945583303 | AC16: 09051762599- | AD16: 09051762599-
A17: 16 | E17: =G17 -> دبیرستان سال یازدهم | F17: مقطع تحصیلی : | G17: دبیرستان سال یازدهم | H17: دبیرستان سال دهم | I17: دبیرستان سال دهم | J17: دبیرستان سال دهم | K17: دبیرستان سال دهم | L17: دبیرستان سال دهم | M17: دبیرستان سال دهم | N17: دبیرستان سال دوازدهم | O17: دبیرستان سال دوازدهم | P17: دبیرستان سال دوازدهم | Q17: دبیرستان سال دهم | R17: دبیرستان سال دهم | S17: دبیرستان سال دوازدهم | T17: دبیرستان سال یازدهم | U17: دبیرستان سال دهم | V17: دبیرستان سال یازدهم | W17: دبیرستان سال دهم | X17: دبیرستان سال دهم | Y17: دبیرستان سال دوازدهم | Z17: دبیرستان سال دهم | AA17: دبستان کلاس اول | AB17: دبستان کلاس پنجم | AC17: دبستان کلاس پنجم | AD17: دبستان کلاس چهارم
A18: 17 | E18: =G18 -> ریاضی | F18: رشته تحصیلی : | G18: ریاضی | H18: انسانی | I18: ریاضی | J18: تجربی | K18: تجربی | L18: ریاضی | M18: انسانی | N18: تجربی | O18: تجربی | P18: ریاضی | Q18: تجربی | R18: انسانی | S18: تجربی | T18: تجربی | U18: تجربی | V18: تجربی | W18: انسانی | X18: تجربی | Y18: ریاضی | Z18: تجربی
A19: 18 | E19: =G19 -> 18/22 | F19: معدل : | G19: 18/22 | H19: 19/62 | I19: 19/48 | J19: 19/24 | K19: 19/05 | L19: 17/99 | M19: 18/99 | N19: 18/68 | O19: 18/74 | P19: 18/47 | Q19: 19/88 | T19: 18/10 | U19: 18/55 | V19: 17 | W19: 19/02 | X19: 19/88 | Z19: 19/83 | AB19: خیلی خوب
A20: 19 | E20: =G20 -> مدرسه حضرت خدیجه- ناحیه تباتکان | F20: آدرس محل تحصیل: | G20: مدرسه حضرت خدیجه- ناحیه تباتکان | H20: مدرسه حضرت خدیجه- ناحیه تباتکان | I20: مدرسه حضرت خدیجه- ناحیه تباتکان | J20: مدرسه حضرت خدیجه- ناحیه تباتکان | K20: مدرسه حضرت خدیجه- ناحیه تباتکان | L20: مدرسه آرمیتا مصلی نژاد- ناحیه تباتکان | M20: مدرسه حضرت خدیجه- ناحیه تباتکان | N20: مدرسه آرمیتا مصلی نژاد- ناحیه تباتکان | O20: مدرسه حضرت خدیجه- ناحیه تباتکان | P20: مدرسه حضرت خدیجه- ناحیه تباتکان | Q20: مدرسه حضرت خدیجه- ناحیه تباتکان | R20: مدرسه آرمیتا مصلی نژاد- ناحیه تباتکان | T20: دبیرستان نرجس دولت آباد | U20: دبیرستان رستگار مقدم | V20: دبیرستان رستگار مقدم | W20: دبیرستان رستگار مقدم | X20: دبیرستان رستگار مقدم | Y20: دبیرستان خدیجه | Z20: دبیرستان رستگار مقدم | AA20: مدرسه بعثت | AB20: مدرسه بعثت | AC20: مدرسه بهادرزاده | AD20: مدرسه بهادرزاده
A21: 20 | E21: =G21 -> 9155008954 | F21: تلفن محل تحصیل: | G21: 9155008954 | H21: 9155008954 | I21: 9155008954 | J21: 9155008954 | K21: 9155008954 | L21: 5136655064 | M21: 9155008954 | N21: 5136655064 | O21: 9155008954 | P21: 9155008954 | Q21: 9155008954 | R21: 5136655064
A22: 21 | E22: =G22 -> زبان انگلیسی و کره ای | F22: استعداد : | G22: زبان انگلیسی و کره ای
A23: 22 | E23: =G23 -> کارآفرینی | F23: علاقه مندی : | G23: کارآفرینی | H23: علاقمند به دبیری | I23: تحصیل در دانشگاه فرهنگیان | J23: علاقمند به رشته پزشکی | K23: علاقمند به رشته پزشکی | L23: علاقمند به رشته مهندسی کامپیوتر | M23: علاقمند به رشته وکالت | N23: علاقمند به رشته پزشکی | O23: علاقمند به رشته پزشکی | P23: علاقمند به | Q23: علاقمند به | R23: علاقمند به دبیری | S23: علاقمند به پزشکی | T23: علاقمند به پزشکی | U23: علاقمند به پزشکی | V23: علاقمندی ندارد | W23: علاقمندی ندارد | X23: علاقمندی به پزشکی | Y23: علاقمندی به گرافیک | Z23: علاقمندی به پزشکی
A24: 23 | E24: =G24 -> 1401/06/15 | F24: تاریخ بررسی : | G24: 1401/06/15 | H24: 1401/06/15 | I24: 1401/06/15 | J24: 1401/06/15 | K24: 1401/06/15 | L24: 1401/06/15 | M24: 1401/06/15 | N24: 1401/06/15 | O24: 1401/06/15 | P24: 1401/06/15 | Q24: 1401/06/15 | R24: 1401/06/15 | S24: 1401/06/15 | T24: 1401/06/15 | U24: 1401/06/15 | V24: 1401/06/15 | W24: 1401/06/15 | X24: 1401/06/15 | Z24: 1401/06/15 | AA24: 1401/06/15 | AB24: 1401/06/15 | AC24: 1401/06/15 | AD24: 1401/06/15
A25: 24 | E25: =G25 -> افسردگی و ناامیدی شدید | F25: سوابق بیماری | G25: افسردگی و ناامیدی شدید
A26: 25 | E26: =G26 -> ندارد | F26: توضیحات بیماری: | G26: ندارد | H26: ندارد | I26: ندارد | J26: ندارد | K26: ندارد | L26: ندارد | M26: ندارد | N26: ندارد | O26: ندارد | P26: ندارد | Q26: ندارد | R26: ندارد | S26: ندارد | T26: ندارد | U26: ندارد | V26: افسردگی شدید | W26: ندارد | X26: ندارد | Y26: ندارد | Z26: ندارد | AA26: ندارد | AB26: ندارد | AC26: ندارد | AD26: ندارد
A27: 26 | E27: =G27 -> 0 | F27: آزمایشات یا چکاپ پزشکی | AA27: دندانهایش توسط دکتر محسنیان عصب کشی گردید
A28: 27 | E28: =G28 -> 0 | F28: توضیحات آزمایش یا چکاپ :
A29: 28 | E29: =G29 -> ندارد | F29: نیاز به خدمات خاصی | G29: ندارد | H29: ندارد | I29: در درس ریاضی احتیاج به کمک دارد. | P29: کتابهای کمک آموزشی لازم دارد | R29: سمعک لازم دارد
A30: 29 | E30: =G30 -> نداد | F30: توضیحات خدمات : | G30: نداد | H30: نداد | I30: ندارد | J30: ندارد | K30: ندارد | L30: ندارد | M30: ندارد | N30: ندارد | O30: ندارد | P30: ندارد | Q30: ندارد | R30: ندارد | S30: ندارد | T30: ندارد | U30: ندارد | V30: ندارد | W30: ندارد | X30: ندارد | Y30: ندارد | Z30: ندارد | AA30: ندارد | AB30: ندارد | AC30: ندارد | AD30: ندارد | AE30: ندارد | AF30: ندارد | AG30: ندارد | AH30: ندارد | AI30: ندارد | AJ30: ندارد | AK30: ندارد | AL30: ندارد | AM30: ندارد | AN30: ندارد | AO30: ندارد
A31: 30 | E31: =G31 -> ‍‍ | G31: ‍‍ | H31: ‍‍ | I31: ‍‍ | J31: ‍‍ | K31: ‍‍ | L31: ‍‍ | M31: ‍‍ | N31: ‍‍ | O31: ‍‍ | P31: ‍‍ | Q31: ‍‍ | R31: ‍‍ | S31: ‍‍ | T31: ‍‍ | U31: ‍‍ | V31: ‍‍ | W31: ‍‍ | X31: ‍‍ | Y31: ‍‍ | Z31: ‍‍ | AA31: ‍‍ | AB31: ‍‍ | AC31: ‍‍ | AD31: ‍‍ | AE31: ‍‍ | AF31: ‍‍ | AG31: ‍‍ | AH31: ‍‍ | AI31: ‍‍ | AJ31: ‍‍ | AK31: ‍‍ | AL31: ‍‍ | AM31: ‍‍ | AN31: ‍‍ | AO31: ‍‍
A32: 31 | E32: =G32 -> 0
A33: 32 | E33: =G33 -> 0
A34: 33 | E34: =G34 -> 0
A35: 34 | E35: =G35 -> 0
A36: 35 | E36: =G36 -> 0
A37: 36 | E37: =G37 -> 0
A38: 37 | E38: =G38 -> 0
A39: 38 | E39: =G39 -> 0
A40: 39 | E40: =G40 -> 0
...

Sheet ریزهزینه کرد مددجوها
A1: ok | B1: ردیف | C1: kkkk | D1: Column1 | E1: کد | F1: نام ونام خانوادگی | G1: شرح هزینه | H1: تاریخ هزینه | I1: شماره فیش | J1: مبلغ هزینه کرد | K1: توضیحات
A2: ok | B2: 1 | F2: =IF(E2="","",HLOOKUP(E2,etela,2,0)) | H2: 1401/03/22 | J2: -60000000
A3: ok | B3: 2 | F3: =IF(E3="","",HLOOKUP(E3,etela,2,0)) | H3: 1401/03/22 | J3: 79520000
A4: ok | B4: 3 | F4: =IF(E4="","",HLOOKUP(E4,etela,2,0)) | H4: 1401/03/23 | J4: 1360000
A5: ok | B5: 4 | F5: =IF(E5="","",HLOOKUP(E5,etela,2,0)) | H5: 1401/03/23 | J5: 360000
A6: ok | B6: 5 | F6: =IF(E6="","",HLOOKUP(E6,etela,2,0)) | H6: 1401/03/23 | J6: 1600000
A7: ok | B7: 6 | F7: =IF(E7="","",HLOOKUP(E7,etela,2,0)) | H7: 1401/03/23 | J7: 5500000
A8: ok | B8: 7 | F8: =IF(E8="","",HLOOKUP(E8,etela,2,0)) | H8: 1401/03/23 | J8: 2025620
A9: ok | B9: 8 | F9: =IF(E9="","",HLOOKUP(E9,etela,2,0)) | H9: 1401/03/24 | J9: 2000000
A10: ok | B10: 9 | F10: =IF(E10="","",HLOOKUP(E10,etela,2,0)) | H10: 1401/03/24 | J10: 2900000
A11: ok | B11: 10 | F11: =IF(E11="","",HLOOKUP(E11,etela,2,0)) | H11: 1401/03/24 | J11: 2300000
A12: ok | B12: 11 | F12: =IF(E12="","",HLOOKUP(E12,etela,2,0)) | G12: کارمزد مانده گیری | H12: 1401/03/25 | J12: 1200
A13: ok | B13: 13 | F13: =IF(E13="","",HLOOKUP(E13,etela,2,0)) | H13: 1401/03/25 | J13: -37024214
J14: =SUM(J2:J13) -> 542606
A16: ok | B16: 14 | E16: 23 | F16: =IF(E16="","",HLOOKUP(E16,etela,2,0)) -> محمدرضا سروری | G16: خرید آذوقه برای خانواده سروری | H16: 1401/03/25 | J16: 3370000
A17: ok | B17: 15 | E17: 24 | F17: =IF(E17="","",HLOOKUP(E17,etela,2,0)) -> کمیل سروری | G17: خرید نان برای خانواده سروری | H17: 1401/03/25 | J17: 104000
A18: ok | B18: 16 | E18: m1 | F18: =IF(E18="","",HLOOKUP(E18,etela,2,0)) -> هزینه کلی به مددجویان | G18: فتوکپی | H18: 1401/03/28 | J18: 14500
A19: ok | B19: 17 | E19: k1 | F19: =IF(E19="","",HLOOKUP(E19,etela,2,0)) -> هزینه کلی موسسه | G19: تمبر بانکداری | H19: 1401/04/01 | J19: 10000
A20: ok | B20: 18 | E20: k1 | F20: =IF(E20="","",HLOOKUP(E20,etela,2,0)) -> هزینه کلی موسسه | G20: تمبر بانکداری | H20: 1401/04/01 | J20: 8000
A21: ok | B21: 19 | E21: k1 | F21: =IF(E21="","",HLOOKUP(E21,etela,2,0)) -> هزینه کلی موسسه | G21: تمبر بانکداری | H21: 1401/04/01 | J21: 18000
A22: ok | B22: 20 | E22: 23 | F22: =IF(E22="","",HLOOKUP(E22,etela,2,0)) -> محمدرضا سروری | G22: خرید لباس فرم مدرسه | H22: 1401/04/01 | J22: 3003000
A23: ok | B23: 21 | C23: =MID('ریزهزینه کرد مددجوها'!$H23,6,2) -> 04 | D23: =MID('ریزهزینه کرد مددجوها'!$H23,1,4) -> 1401 | E23: 24 | F23: =IF(E23="","",HLOOKUP(E23,etela,2,0)) -> کمیل سروری | G23: خرید لباس فرم مدرسه | H23: 1401/04/01 | J23: 3003000
A24: ok | B24: 22 | C24: =MID('ریزهزینه کرد مددجوها'!$H24,6,2) -> 04 | D24: =MID('ریزهزینه کرد مددجوها'!$H24,1,4) -> 1401 | E24: 21 | F24: =IF(E24="","",HLOOKUP(E24,etela,2,0)) -> ملبکا نماز | G24: خرید لباس فرم مدرسه | H24: 1401/04/01 | J24: 2960000
A25: ok | B25: 23 | C25: =MID('ریزهزینه کرد مددجوها'!$H25,6,2) -> 04 | D25: =MID('ریزهزینه کرد مددجوها'!$H25,1,4) -> 1401 | E25: 21 | F25: =IF(E25="","",HLOOKUP(E25,etela,2,0)) -> ملبکا نماز | G25: ثبت نام مدرسه | H25: 1401/04/01 | J25: 3706000
A26: ok | B26: 24 | C26: =MID('ریزهزینه کرد مددجوها'!$H26,6,2) -> 04 | D26: =MID('ریزهزینه کرد مددجوها'!$H26,1,4) -> 1401 | E26: k1 | F26: =IF(E26="","",HLOOKUP(E26,etela,2,0)) -> هزینه کلی موسسه | G26: کارمزد پیامک بانک | H26: 1401/04/07 | J26: 200000
A27: ok | B27: 25 | E27: m1 | F27: =IF(E27="","",HLOOKUP(E27,etela,2,0)) -> هزینه کلی به مددجویان | G27: خرید شیرینی برای بازدید از منازل | H27: 1401/05/10 | J27: 3420000
A28: ok | B28: 26 | E28: 20 | F28: =IF(E28="","",HLOOKUP(E28,etela,2,0)) -> پری زارع | G28: خرید پنکه پایه دار | H28: 1401/05/12 | J28: 16508400
A29: ok | B29: 27 | C29: =MID('ریزهزینه کرد مددجوها'!$H29,6,2) -> 05 | D29: =MID('ریزهزینه کرد مددجوها'!$H29,1,4) -> 1401 | E29: 20 | F29: =IF(E29="","",HLOOKUP(E29,etela,2,0)) -> پری زارع | G29: هزینه پیک موتوری | H29: 1401/05/12 | J29: 250000
A30: ok | B30: 28 | C30: =MID('ریزهزینه کرد مددجوها'!$H30,6,2) -> 05 | D30: =MID('ریزهزینه کرد مددجوها'!$H30,1,4) -> 1401 | E30: 20 | F30: =IF(E30="","",HLOOKUP(E30,etela,2,0)) -> پری زارع | G30: هزینه خرید گوشت و مرغ | H30: 1401/05/12 | J30: 4080000
A31: ok | B31: 29 | C31: =MID('ریزهزینه کرد مددجوها'!$H31,6,2) -> 05 | D31: =MID('ریزهزینه کرد مددجوها'!$H31,1,4) -> 1401 | E31: m1 | F31: =IF(E31="","",HLOOKUP(E31,etela,2,0)) -> هزینه کلی به مددجویان | G31: خرید شیرینی برای بازدید از منازل | H31: 1401/05/12 | J31: 2252500
A32: ok | B32: 30 | E32: k1 | F32: =IF(E32="","",HLOOKUP(E32,etela,2,0)) -> هزینه کلی موسسه | G32: هزینه تعمیر گازمدرسه رستگار مقدم | H32: 1401/06/14 | J32: 10006000
A33: ok | B33: 31 | E33: k1 | F33: =IF(E33="","",HLOOKUP(E33,etela,2,0)) -> هزینه کلی موسسه | G33: هزینه خرید گل آرمین متقی(توسط فرید برهان علمی) | H33: 1401/06/12 | J33: 10006000
A34: ok | B34: 32 | C34: =MID('ریزهزینه کرد مددجوها'!$H34,6,2) -> 06 | D34: =MID('ریزهزینه کرد مددجوها'!$H34,1,4) -> 1401 | E34: k1 | F34: =IF(E34="","",HLOOKUP(E34,etela,2,0)) -> هزینه کلی موسسه | G34: بابت پرینت تراکنشهای بانکی | H34: 1401/06/15 | J34: 24000
A35: ok | B35: 33 | E35: 6 | F35: =IF(E35="","",HLOOKUP(E35,etela,2,0)) -> راضیه رضاپور | G35: هزینه ثبت نام مدرسه مصلی نژاد | H35: 1401/06/17 | J35: 25010800
A36: ok | B36: 34 | E36: 6 | F36: =IF(E36="","",HLOOKUP(E36,etela,2,0)) -> راضیه رضاپور | G36: خرید لباس فرم مدرسه | H36: 1401/06/17 | J36: 4256000
A37: ok | B37: 35 | E37: m1 | F37: =IF(E37="","",HLOOKUP(E37,etela,2,0)) -> هزینه کلی به مددجویان | G37: خرید آذوقه برای 5 خانواده از مددجوها | H37: 1401/06/23 | J37: 20400000
A38: ok | B38: 36 | E38: k1 | F38: =IF(E38="","",HLOOKUP(E38,etela,2,0)) -> هزینه کلی موسسه | G38: هزینه کرایه وانت جهت حمل به انبار(توسط بهنام بهرمن) | H38: 1401/05/15 | J38: 4000000
A39: ok | B39: 37 | C39: =MID('ریزهزینه کرد مددجوها'!$H39,6,2) -> 06 | D39: =MID('ریزهزینه کرد مددجوها'!$H39,1,4) -> 1401 | E39: k1 | F39: =IF(E39="","",HLOOKUP(E39,etela,2,0)) -> هزینه کلی موسسه | G39: تسویه هزینه تعمیر گازمدرسه رستگار مقدم | H39: 1401/06/15 | J39: 7006000
A40: ok | B40: 38 | E40: k1 | F40: =IF(E40="","",HLOOKUP(E40,etela,2,0)) -> هزینه کلی موسسه | G40: خریدلوازم تحریر کودکان خیریه مهبد(ضرابی) | H40: 1401/06/23 | J40: 15577400
A41: ok | B41: 39 | C41: =MID('ریزهزینه کرد مددجوها'!$H41,6,2) -> 06 | D41: =MID('ریزهزینه کرد مددجوها'!$H41,1,4) -> 1401 | E41: m1 | F41: =IF(E41="","",HLOOKUP(E41,etela,2,0)) -> هزینه کلی به مددجویان | G41: خریدلوازم تحریر کودکان | H41: 1401/06/23 | J41: 44023100
...

Sheet خلاصه هزینه کرد مددجوها
C1: کل مانده | D1: ='لیست واریزی کل خیرین'!$H$142-'خلاصه هزینه کرد مددجوها'!$D$124 -> 10204190839
B2: کد مددجو | C2: نام و نام خانوادگی | D2: مبلغ هزینه کرد
B3: m1 | C3: =IF(B3="","",HLOOKUP(B3,etela,2,0)) -> هزینه کلی به مددجویان | D3: =SUMIF('ریزهزینه کرد مددجوها'!E:E,'خلاصه هزینه کرد مددجوها'!B3,'ریزهزینه کرد مددجوها'!J:J) -> 768134600
B4: k1 | C4: =IF(B4="","",HLOOKUP(B4,etela,2,0)) -> هزینه کلی موسسه | D4: =SUMIF('ریزهزینه کرد مددجوها'!E:E,'خلاصه هزینه کرد مددجوها'!B4,'ریزهزینه کرد مددجوها'!J:J) -> 4007434580
B5: S | C5: هزینه مربوط به تعمیرات مدارس از واریزی خانم عین علی | D5: =SUMIF('ریزهزینه کرد مددجوها'!E:E,'خلاصه هزینه کرد مددجوها'!B5,'ریزهزینه کرد مددجوها'!J:J) -> 45000000
B6: 1 | C6: =IF(B6="","",HLOOKUP(B6,etela,2,0)) -> ریحانه نوری شفیق | D6: =SUMIF('ریزهزینه کرد مددجوها'!E:E,'خلاصه هزینه کرد مددجوها'!B6,'ریزهزینه کرد مددجوها'!J:J) -> 11985000
B7: 2 | C7: =IF(B7="","",HLOOKUP(B7,etela,2,0)) -> ریحانه طراقی فرد | D7: =SUMIF('ریزهزینه کرد مددجوها'!E:E,'خلاصه هزینه کرد مددجوها'!B7,'ریزهزینه کرد مددجوها'!J:J) -> 0
B8: 3 | C8: =IF(B8="","",HLOOKUP(B8,etela,2,0)) -> زهرا قهستانی | D8: =SUMIF('ریزهزینه کرد مددجوها'!E:E,'خلاصه هزینه کرد مددجوها'!B8,'ریزهزینه کرد مددجوها'!J:J) -> 4700000
B9: 4 | C9: =IF(B9="","",HLOOKUP(B9,etela,2,0)) -> مهلا قهستانی | D9: =SUMIF('ریزهزینه کرد مددجوها'!E:E,'خلاصه هزینه کرد مددجوها'!B9,'ریزهزینه کرد مددجوها'!J:J) -> 4800000
B10: 5 | C10: =IF(B10="","",HLOOKUP(B10,etela,2,0)) -> رقیه رضاپور | D10: =SUMIF('ریزهزینه کرد مددجوها'!E:E,'خلاصه هزینه کرد مددجوها'!B10,'ریزهزینه کرد مددجوها'!J:J) -> 4700000
B11: 6 | C11: =IF(B11="","",HLOOKUP(B11,etela,2,0)) -> راضیه رضاپور | D11: =SUMIF('ریزهزینه کرد مددجوها'!E:E,'خلاصه هزینه کرد مددجوها'!B11,'ریزهزینه کرد مددجوها'!J:J) -> 31678800
B12: 7 | C12: =IF(B12="","",HLOOKUP(B12,etela,2,0)) -> ربابه رضاپور | D12: =SUMIF('ریزهزینه کرد مددجوها'!E:E,'خلاصه هزینه کرد مددجوها'!B12,'ریزهزینه کرد مددجوها'!J:J) -> 4900000
B13: 8 | C13: =IF(B13="","",HLOOKUP(B13,etela,2,0)) -> پریسا اعتمادمنش | D13: =SUMIF('ریزهزینه کرد مددجوها'!E:E,'خلاصه هزینه کرد مددجوها'!B13,'ریزهزینه کرد مددجوها'!J:J) -> 100008400 | I13: `
B14: 9 | C14: =IF(B14="","",HLOOKUP(B14,etela,2,0)) -> فاطمه موسوی | D14: =SUMIF('ریزهزینه کرد مددجوها'!E:E,'خلاصه هزینه کرد مددجوها'!B14,'ریزهزینه کرد مددجوها'!J:J) -> 5072000
B15: 10 | C15: =IF(B15="","",HLOOKUP(B15,etela,2,0)) -> مریم رحمانی | D15: =SUMIF('ریزهزینه کرد مددجوها'!E:E,'خلاصه هزینه کرد مددجوها'!B15,'ریزهزینه کرد مددجوها'!J:J) -> 10256000
B16: 11 | C16: =IF(B16="","",HLOOKUP(B16,etela,2,0)) -> ناهید کمالی گروی | D16: =SUMIF('ریزهزینه کرد مددجوها'!E:E,'خلاصه هزینه کرد مددجوها'!B16,'ریزهزینه کرد مددجوها'!J:J) -> 5156000
B17: 12 | C17: =IF(B17="","",HLOOKUP(B17,etela,2,0)) -> الهام صمدی | D17: =SUMIF('ریزهزینه کرد مددجوها'!E:E,'خلاصه هزینه کرد مددجوها'!B17,'ریزهزینه کرد مددجوها'!J:J) -> 81775200
B18: 13 | C18: =IF(B18="","",HLOOKUP(B18,etela,2,0)) -> کوثر مولایی | D18: =SUMIF('ریزهزینه کرد مددجوها'!E:E,'خلاصه هزینه کرد مددجوها'!B18,'ریزهزینه کرد مددجوها'!J:J) -> 15443500
B19: 14 | C19: =IF(B19="","",HLOOKUP(B19,etela,2,0)) -> زهرا تاتاری | D19: =SUMIF('ریزهزینه کرد مددجوها'!E:E,'خلاصه هزینه کرد مددجوها'!B19,'ریزهزینه کرد مددجوها'!J:J) -> 4430000
B20: 15 | C20: =IF(B20="","",HLOOKUP(B20,etela,2,0)) -> یگانه رجایی سمرا | D20: =SUMIF('ریزهزینه کرد مددجوها'!E:E,'خلاصه هزینه کرد مددجوها'!B20,'ریزهزینه کرد مددجوها'!J:J) -> 1206000
B21: 16 | C21: =IF(B21="","",HLOOKUP(B21,etela,2,0)) -> یگانه خرمند سنجدبوری | D21: =SUMIF('ریزهزینه کرد مددجوها'!E:E,'خلاصه هزینه کرد مددجوها'!B21,'ریزهزینه کرد مددجوها'!J:J) -> 5183000
B22: 17 | C22: =IF(B22="","",HLOOKUP(B22,etela,2,0)) -> کوثر فارقی | D22: =SUMIF('ریزهزینه کرد مددجوها'!E:E,'خلاصه هزینه کرد مددجوها'!B22,'ریزهزینه کرد مددجوها'!J:J) -> 3674000
B23: 18 | C23: =IF(B23="","",HLOOKUP(B23,etela,2,0)) -> ریحانه نجفی | D23: =SUMIF('ریزهزینه کرد مددجوها'!E:E,'خلاصه هزینه کرد مددجوها'!B23,'ریزهزینه کرد مددجوها'!J:J) -> 0
B24: 19 | C24: =IF(B24="","",HLOOKUP(B24,etela,2,0)) -> نادیا احمدی | D24: =SUMIF('ریزهزینه کرد مددجوها'!E:E,'خلاصه هزینه کرد مددجوها'!B24,'ریزهزینه کرد مددجوها'!J:J) -> 2506000
B25: 20 | C25: =IF(B25="","",HLOOKUP(B25,etela,2,0)) -> پری زارع | D25: =SUMIF('ریزهزینه کرد مددجوها'!E:E,'خلاصه هزینه کرد مددجوها'!B25,'ریزهزینه کرد مددجوها'!J:J) -> 20838400
... B30: 25 | C30: =IF(B30="","",HLOOKUP(B30,etela,2,0)) -> مبینا عباسی | D30: =SUMIF('ریزهزینه کرد مددجوها'!E:E,'خلاصه هزینه کرد مددجوها'!B30,'ریزهزینه کرد مددجوها'!J:J) -> 5070000
B31: 26 | C31: =IF(B31="","",HLOOKUP(B31,kamel,2,0)) -> الناز حبیب زاده | D31: =SUMIF('ریزهزینه کرد مددجوها'!E:E,'خلاصه هزینه کرد مددجوها'!B31,'ریزهزینه کرد مددجوها'!J:J) -> 0
B32: 27 | C32: =IF(B32="","",HLOOKUP(B32,kamel,2,0)) -> نرگس علینژاد | D32: =SUMIF('ریزهزینه کرد مددجوها'!E:E,'خلاصه هزینه کرد مددجوها'!B32,'ریزهزینه کرد مددجوها'!J:J) -> 42117600
B33: 28 | C33: =IF(B33="","",HLOOKUP(B33,kamel,2,0)) -> زینب ادبی یکه باغی | D33: =SUMIF('ریزهزینه کرد مددجوها'!E:E,'خلاصه هزینه کرد مددجوها'!B33,'ریزهزینه کرد مددجوها'!J:J) -> 8967200
B34: 29 | C34: =IF(B34="","",HLOOKUP(B34,kamel,2,0)) -> آتنا جر | D34: =SUMIF('ریزهزینه کرد مددجوها'!E:E,'خلاصه هزینه کرد مددجوها'!B34,'ریزهزینه کرد مددجوها'!J:J) -> 55385240
B35: 30 | C35: =IF(B35="","",HLOOKUP(B35,kamel,2,0)) -> مبینا علیزاده | D35: =SUMIF('ریزهزینه کرد مددجوها'!E:E,'خلاصه هزینه کرد مددجوها'!B35,'ریزهزینه کرد مددجوها'!J:J) -> 6362000
B36: 31 | C36: =IF(B36="","",HLOOKUP(B36,kamel,2,0)) -> یگانه محمددوست | D36: =SUMIF('ریزهزینه کرد مددجوها'!E:E,'خلاصه هزینه کرد مددجوها'!B36,'ریزهزینه کرد مددجوها'!J:J) -> 8723500
B37: 32 | C37: =IF(B37="","",HLOOKUP(B37,kamel,2,0)) -> رقیه الزوینی | D37: =SUMIF('ریزهزینه کرد مددجوها'!E:E,'خلاصه هزینه کرد مددجوها'!B37,'ریزهزینه کرد مددجوها'!J:J) -> 9648500
B38: 33 | C38: =IF(B38="","",HLOOKUP(B38,kamel,2,0)) -> عارفه آذرنگ | D38: =SUMIF('ریزهزینه کرد مددجوها'!E:E,'خلاصه هزینه کرد مددجوها'!B38,'ریزهزینه کرد مددجوها'!J:J) -> 16550900
B39: 34 | C39: =IF(B39="","",HLOOKUP(B39,kamel,2,0)) -> یگانه عبدالله زاده | D39: =SUMIF('ریزهزینه کرد مددجوها'!E:E,'خلاصه هزینه کرد مددجوها'!B39,'ریزهزینه کرد مددجوها'!J:J) -> 33129194
B40: 35 | C40: =IF(B40="","",HLOOKUP(B40,kamel,2,0)) -> ثنا پور دوران | D40: =SUMIF('ریزهزینه کرد مددجوها'!E:E,'خلاصه هزینه کرد مددجوها'!B40,'ریزهزینه کرد مددجوها'!J:J) -> 0
B41: 36 | C41: =IF(B41="","",HLOOKUP(B41,kamel,2,0)) -> هدیه محمد پور جاغرق | D41: =SUMIF('ریزهزینه کرد مددجوها'!E:E,'خلاصه هزینه کرد مددجوها'!B41,'ریزهزینه کرد مددجوها'!J:J) -> 0
B42: 37 | C42: =IF(B42="","",HLOOKUP(B42,kamel,2,0)) -> کوثر صفری | D42: =SUMIF('ریزهزینه کرد مددجوها'!E:E,'خلاصه هزینه کرد مددجوها'!B42,'ریزهزینه کرد مددجوها'!J:J) -> 0
... B84: 79 | C84: =IF(B84="","",HLOOKUP(B84,kamel,2,0)) -> #N/A | D84: =SUMIF('ریزهزینه کرد مددجوها'!E:E,'خلاصه هزینه کرد مددجوها'!B84,'ریزهزینه کرد مددجوها'!J:J) -> 0
B85: 80 | C85: =IF(B85="","",HLOOKUP(B85,etela,2,0)) -> #N/A | D85: =SUMIF('ریزهزینه کرد مددجوها'!E:E,'خلاصه هزینه کرد مددجوها'!B85,'ریزهزینه کرد مددجوها'!J:J) -> 0
...

Sheet لیست واریزی ماهیانه
A1: Column1 | B1: ردیف | C1: نام | D1: نام خانوادگی | E1: تاریخ واریزی | F1: شماره کارت | G1: ماه | H1: Column2 | I1: سال | J1: شماره فیش | K1: مبلغ واریزی | L1: توضیحات ‍‍‍‍ | M1: Column3
A2: ok | B2: =SUMIFS('لیست واریزی کل خیرین'!B:B,'لیست واریزی کل خیرین'!D:D,Table1[[#This Row],[نام]],'لیست واریزی کل خیرین'!E:E,Table1[[#This Row],[نام خانوادگی]]) -> 22 | C2: عطا | D2: امیدوار | E2: 1401/04/01 | F2: 5.029081e+15 | G2: خرداد | H2: =IF(G2="","",VLOOKUP(G2,mah,2,0)) -> 3 | I2: 1401 | K2: 2000000 | Q2: فروردین | R2: 1
A3: ok | B3: =SUMIFS('لیست واریزی کل خیرین'!B:B,'لیست واریزی کل خیرین'!D:D,Table1[[#This Row],[نام]],'لیست واریزی کل خیرین'!E:E,Table1[[#This Row],[نام خانوادگی]]) -> 8 | C3: داوود | D3: بامیری | E3: 1401/03/25 | F3: 6.1043379e+15 | G3: خرداد | H3: =IF(G3="","",VLOOKUP(G3,mah,2,0)) -> 3 | I3: 1401 | K3: 5000000 | Q3: اردیبهشت | R3: 2
A4: ok | B4: =SUMIFS('لیست واریزی کل خیرین'!B:B,'لیست واریزی کل خیرین'!D:D,Table1[[#This Row],[نام]],'لیست واریزی کل خیرین'!E:E,Table1[[#This Row],[نام خانوادگی]]) -> 63 | C4: سود | D4: بانکی | E4: 1401/03/31 | F4: ---------------- | G4: خرداد | H4: =IF(G4="","",VLOOKUP(G4,mah,2,0)) -> 3 | I4: 1401 | K4: 4570 | Q4: خرداد | R4: 3
A5: ok | B5: =SUMIFS('لیست واریزی کل خیرین'!B:B,'لیست واریزی کل خیرین'!D:D,Table1[[#This Row],[نام]],'لیست واریزی کل خیرین'!E:E,Table1[[#This Row],[نام خانوادگی]]) -> 20 | C5: محمد | D5: برجسته | E5: 1401/03/30 | F5: 6.0376976e+15 | G5: خرداد | H5: =IF(G5="","",VLOOKUP(G5,mah,2,0)) -> 3 | I5: 1401 | K5: 10000000 | Q5: تیر | R5: 4
A6: ok | B6: =SUMIFS('لیست واریزی کل خیرین'!B:B,'لیست واریزی کل خیرین'!D:D,Table1[[#This Row],[نام]],'لیست واریزی کل خیرین'!E:E,Table1[[#This Row],[نام خانوادگی]]) -> 1 | C6: فرید | D6: برهان علمی | E6: 1401/03/25 | F6: 6.1043376e+15 | G6: خرداد | H6: =IF(G6="","",VLOOKUP(G6,mah,2,0)) -> 3 | I6: 1401 | K6: 10000000 | Q6: مرداد | R6: 5
A7: ok | B7: =SUMIFS('لیست واریزی کل خیرین'!B:B,'لیست واریزی کل خیرین'!D:D,Table1[[#This Row],[نام]],'لیست واریزی کل خیرین'!E:E,Table1[[#This Row],[نام خانوادگی]]) -> 2 | C7: بهنام | D7: بهرمن | E7: 1401/03/23 | F7: خاتم عطیه نادری | G7: خرداد | H7: =IF(G7="","",VLOOKUP(G7,mah,2,0)) -> 3 | I7: 1401 | K7: 20000000 | Q7: شهریور | R7: 6
A8: ok | B8: =SUMIFS('لیست واریزی کل خیرین'!B:B,'لیست واریزی کل خیرین'!D:D,Table1[[#This Row],[نام]],'لیست واریزی کل خیرین'!E:E,Table1[[#This Row],[نام خانوادگی]]) -> 4 | C8: فرهنگ | D8: بهلول | E8: 1401/03/24 | F8: 6.219861e+15 | G8: خرداد | H8: =IF(G8="","",VLOOKUP(G8,mah,2,0)) -> 3 | I8: 1401 | K8: 2000000 | Q8: مهر | R8: 7
A9: ok | B9: =SUMIFS('لیست واریزی کل خیرین'!B:B,'لیست واریزی کل خیرین'!D:D,Table1[[#This Row],[نام]],'لیست واریزی کل خیرین'!E:E,Table1[[#This Row],[نام خانوادگی]]) -> 9 | C9: مجتبی | D9: حسن آبادی | E9: 1401/03/25 | F9: 6.0376915e+15 | G9: خرداد | H9: =IF(G9="","",VLOOKUP(G9,mah,2,0)) -> 3 | I9: 1401 | K9: 5000000 | Q9: آبان | R9: 8
A10: ok | B10: =SUMIFS('لیست واریزی کل خیرین'!B:B,'لیست واریزی کل خیرین'!D:D,Table1[[#This Row],[نام]],'لیست واریزی کل خیرین'!E:E,Table1[[#This Row],[نام خانوادگی]]) -> 11 | C10: رضا | D10: حسینی | E10: 1401/03/26 | F10: 6.063731e+15 | G10: خرداد | H10: =IF(G10="","",VLOOKUP(G10,mah,2,0)) -> 3 | I10: 1401 | K10: 20000000 | Q10: آذر | R10: 9
A11: ok | B11: =SUMIFS('لیست واریزی کل خیرین'!B:B,'لیست واریزی کل خیرین'!D:D,Table1[[#This Row],[نام]],'لیست واریزی کل خیرین'!E:E,Table1[[#This Row],[نام خانوادگی]]) -> 7 | C11: احسان | D11: خدیوی | E11: 1401/03/25 | F11: 6.0379919e+15 | G11: خرداد | H11: =IF(G11="","",VLOOKUP(G11,mah,2,0)) -> 3 | I11: 1401 | K11: 5000000 | Q11: دی | R11: 10
A12: ok | B12: =SUMIFS('لیست واریزی کل خیرین'!B:B,'لیست واریزی کل خیرین'!D:D,Table1[[#This Row],[نام]],'لیست واریزی کل خیرین'!E:E,Table1[[#This Row],[نام خانوادگی]]) -> 7 | C12: احسان | D12: خدیوی | E12: 1401/03/30 | F12: 6.0379919e+15 | G12: خرداد | H12: =IF(G12="","",VLOOKUP(G12,mah,2,0)) -> 3 | I12: 1401 | K12: 5000000 | L12: واریز دوم | Q12: بهمن | R12: 11
A13: ok | B13: =SUMIFS('لیست واریزی کل خیرین'!B:B,'لیست واریزی کل خیرین'!D:D,Table1[[#This Row],[نام]],'لیست واریزی کل خیرین'!E:E,Table1[[#This Row],[نام خانوادگی]]) -> 18 | C13: آرش | D13: رجب پور | E13: 1401/03/29 | F13: 5.0541616e+17 | G13: خرداد | H13: =IF(G13="","",VLOOKUP(G13,mah,2,0)) -> 3 | I13: 1401 | K13: 50000000 | Q13: اسفند | R13: 12
A14: ok | B14: =SUMIFS('لیست واریزی کل خیرین'!B:B,'لیست واریزی کل خیرین'!D:D,Table1[[#This Row],[نام]],'لیست واریزی کل خیرین'!E:E,Table1[[#This Row],[نام خانوادگی]]) -> 12 | C14: محمد | D14: رکن | E14: 1401/03/26 | F14: 5.0222915e+15 | G14: خرداد | H14: =IF(G14="","",VLOOKUP(G14,mah,2,0)) -> 3 | I14: 1401 | K14: 5000000
A15: ok | B15: =SUMIFS('لیست واریزی کل خیرین'!B:B,'لیست واریزی کل خیرین'!D:D,Table1[[#This Row],[نام]],'لیست واریزی کل خیرین'!E:E,Table1[[#This Row],[نام خانوادگی]]) -> 14 | C15: حسین | D15: زرنگیان | E15: 1401/03/26 | F15: 5.057851e+15 | G15: خرداد | H15: =IF(G15="","",VLOOKUP(G15,mah,2,0)) -> 3 | I15: 1401 | K15: 10000000
A16: ok | B16: =SUMIFS('لیست واریزی کل خیرین'!B:B,'لیست واریزی کل خیرین'!D:D,Table1[[#This Row],[نام]],'لیست واریزی کل خیرین'!E:E,Table1[[#This Row],[نام خانوادگی]]) -> 17 | C16: حمیدرضا | D16: شکوهی زاده | E16: 1401/03/29 | F16: 6.1043379e+15 | G16: خرداد | H16: =IF(G16="","",VLOOKUP(G16,mah,2,0)) -> 3 | I16: 1401 | K16: 15000000
A17: ok | B17: =SUMIFS('لیست واریزی کل خیرین'!B:B,'لیست واریزی کل خیرین'!D:D,Table1[[#This Row],[نام]],'لیست واریزی کل خیرین'!E:E,Table1[[#This Row],[نام خانوادگی]]) -> 16 | C17: محمد | D17: صاحبکار | E17: 1401/03/29 | F17: 6.0379981e+15 | G17: خرداد | H17: =IF(G17="","",VLOOKUP(G17,mah,2,0)) -> 3 | I17: 1401 | K17: 3000000 | L17: اصل فیش واریزی 500 هزار تومان بوده است که 200 هزار تومان برای تیرماه لحاظ میشود
A18: ok | B18: =SUMIFS('لیست واریزی کل خیرین'!B:B,'لیست واریزی کل خیرین'!D:D,Table1[[#This Row],[نام]],'لیست واریزی کل خیرین'!E:E,Table1[[#This Row],[نام خانوادگی]]) -> 6 | C18: مهدی | D18: صنوبری | E18: 1401/03/21 | F18: 6.0376975e+15 | G18: خرداد | H18: =IF(G18="","",VLOOKUP(G18,mah,2,0)) -> 3 | I18: 1401 | K18: 5000000
A19: ok | B19: =SUMIFS('لیست واریزی کل خیرین'!B:B,'لیست واریزی کل خیرین'!D:D,Table1[[#This Row],[نام]],'لیست واریزی کل خیرین'!E:E,Table1[[#This Row],[نام خانوادگی]]) -> 10 | C19: فرزاد | D19: فرشید | E19: 1401/03/26 | F19: ------- | G19: خرداد | H19: =IF(G19="","",VLOOKUP(G19,mah,2,0)) -> 3 | I19: 1401 | K19: 100000000
A20: ok | B20: =SUMIFS('لیست واریزی کل خیرین'!B:B,'لیست واریزی کل خیرین'!D:D,Table1[[#This Row],[نام]],'لیست واریزی کل خیرین'!E:E,Table1[[#This Row],[نام خانوادگی]]) -> 3 | C20: اکبر | D20: قدس روحانی | E20: 1401/03/21 | F20: 6.0376976e+15 | G20: خرداد | H20: =IF(G20="","",VLOOKUP(G20,mah,2,0)) -> 3 | I20: 1401 | K20: 30000000
A21: ok | B21: =SUMIFS('لیست واریزی کل خیرین'!B:B,'لیست واریزی کل خیرین'!D:D,Table1[[#This Row],[نام]],'لیست واریزی کل خیرین'!E:E,Table1[[#This Row],[نام خانوادگی]]) -> 15 | C21: حمید | D21: قربانی | E21: 1401/03/28 | F21: 5.8946318e+15 | G21: خرداد | H21: =IF(G21="","",VLOOKUP(G21,mah,2,0)) -> 3 | I21: 1401 | K21: 10000000
A22: ok | B22: =SUMIFS('لیست واریزی کل خیرین'!B:B,'لیست واریزی کل خیرین'!D:D,Table1[[#This Row],[نام]],'لیست واریزی کل خیرین'!E:E,Table1[[#This Row],[نام خانوادگی]]) -> 19 | C22: رضا | D22: کهلایی | E22: 1401/03/29 | F22: -------------- | G22: خرداد | H22: =IF(G22="","",VLOOKUP(G22,mah,2,0)) -> 3 | I22: 1401 | K22: 20000000
A23: ok | B23: =SUMIFS('لیست واریزی کل خیرین'!B:B,'لیست واریزی کل خیرین'!D:D,Table1[[#This Row],[نام]],'لیست واریزی کل خیرین'!E:E,Table1[[#This Row],[نام خانوادگی]]) -> 13 | C23: مجتبی | D23: معدنی | E23: 1401/03/28 | F23: 6.2198611e+15 | G23: خرداد | H23: =IF(G23="","",VLOOKUP(G23,mah,2,0)) -> 3 | I23: 1401 | K23: 2500000 | L23: گل واریزی یک میلیون تومن برای 4 ماه
A24: ok | B24: =SUMIFS('لیست واریزی کل خیرین'!B:B,'لیست واریزی کل خیرین'!D:D,Table1[[#This Row],[نام]],'لیست واریزی کل خیرین'!E:E,Table1[[#This Row],[نام خانوادگی]]) -> 5 | C24: مسعود | D24: مهدیزاده | E24: 1401/03/24 | F24: 5.8598312e+15 | G24: خرداد | H24: =IF(G24="","",VLOOKUP(G24,mah,2,0)) -> 3 | I24: 1401 | K24: 5000000
A25: ok | B25: =SUMIFS('لیست واریزی کل خیرین'!B:B,'لیست واریزی کل خیرین'!D:D,Table1[[#This Row],[نام]],'لیست واریزی کل خیرین'!E:E,Table1[[#This Row],[نام خانوادگی]]) -> 21 | C25: محمد | D25: موسوی | E25: 1401/03/31 | F25: 5.022291e+15 | G25: خرداد | H25: =IF(G25="","",VLOOKUP(G25,mah,2,0)) -> 3 | I25: 1401 | K25: 5000000
A26: ok | B26: =SUMIFS('لیست واریزی کل خیرین'!B:B,'لیست واریزی کل خیرین'!D:D,Table1[[#This Row],[نام]],'لیست واریزی کل خیرین'!E:E,Table1[[#This Row],[نام خانوادگی]]) -> 23 | C26: علیرضا | D26: مولایی | E26: 1401/04/01 | F26: 5.022291e+15 | G26: خرداد | H26: =IF(G26="","",VLOOKUP(G26,mah,2,0)) -> 3 | I26: 1401 | K26: 10000000
A27: ok | B27: =SUMIFS('لیست واریزی کل خیرین'!B:B,'لیست واریزی کل خیرین'!D:D,Table1[[#This Row],[نام]],'لیست واریزی کل خیرین'!E:E,Table1[[#This Row],[نام خانوادگی]]) -> 28 | C27: عماد | D27: احتشام | E27: 1401/04/23 | F27: 6.0379972e+15 | G27: تیر | H27: =IF(G27="","",VLOOKUP(G27,mah,2,0)) -> 4 | I27: 1401 | K27: 10000000 | L27: (900+100)
A28: ok | B28: =SUMIFS('لیست واریزی کل خیرین'!B:B,'لیست واریزی کل خیرین'!D:D,Table1[[#This Row],[نام]],'لیست واریزی کل خیرین'!E:E,Table1[[#This Row],[نام خانوادگی]]) -> 22 | C28: عطا | D28: امیدوار | E28: 1401/04/29 | F28: 5.029081e+15 | G28: تیر | H28: =IF(G28="","",VLOOKUP(G28,mah,2,0)) -> 4 | I28: 1401 | K28: 2000000
A29: ok | B29: =SUMIFS('لیست واریزی کل خیرین'!B:B,'لیست واریزی کل خیرین'!D:D,Table1[[#This Row],[نام]],'لیست واریزی کل خیرین'!E:E,Table1[[#This Row],[نام خانوادگی]]) -> 30 | C29: خانم | D29: امین آقایی | E29: 1401/04/24 | F29: 5.022291e+15 | G29: تیر | H29: =IF(G29="","",VLOOKUP(G29,mah,2,0)) -> 4 | I29: 1401 | K29: 10000000
A30: ok | B30: =SUMIFS('لیست واریزی کل خیرین'!B:B,'لیست واریزی کل خیرین'!D:D,Table1[[#This Row],[نام]],'لیست واریزی کل خیرین'!E:E,Table1[[#This Row],[نام خانوادگی]]) -> 8 | C30: داوود | D30: بامیری | E30: 1401/04/16 | F30: 6.1043376e+15 | G30: تیر | H30: =IF(G30="","",VLOOKUP(G30,mah,2,0)) -> 4 | I30: 1401 | K30: 5000000
A31: ok | B31: =SUMIFS('لیست واریزی کل خیرین'!B:B,'لیست واریزی کل خیرین'!D:D,Table1[[#This Row],[نام]],'لیست واریزی کل خیرین'!E:E,Table1[[#This Row],[نام خانوادگی]]) -> 63 | C31: سود | D31: بانکی | E31: 1401/04/22 | F31: ---------------- | G31: تیر | H31: =IF(G31="","",VLOOKUP(G31,mah,2,0)) -> 4 | I31: 1401 | K31: 61172
A32: ok | B32: =SUMIFS('لیست واریزی کل خیرین'!B:B,'لیست واریزی کل خیرین'!D:D,Table1[[#This Row],[نام]],'لیست واریزی کل خیرین'!E:E,Table1[[#This Row],[نام خانوادگی]]) -> 20 | C32: محمد | D32: برجسته | E32: 1401/04/29 | F32: 6.0376976e+15 | G32: تیر | H32: =IF(G32="","",VLOOKUP(G32,mah,2,0)) -> 4 | I32: 1401 | K32: 10000000
A33: ok | B33: =SUMIFS('لیست واریزی کل خیرین'!B:B,'لیست واریزی کل خیرین'!D:D,Table1[[#This Row],[نام]],'لیست واریزی کل خیرین'!E:E,Table1[[#This Row],[نام خانوادگی]]) -> 1 | C33: فرید | D33: برهان علمی | E33: 1401/04/21 | F33: 6.1043376e+15 | G33: تیر | H33: =IF(G33="","",VLOOKUP(G33,mah,2,0)) -> 4 | I33: 1401 | K33: 10000000
B34: =SUMIFS('لیست واریزی کل خیرین'!B:B,'لیست واریزی کل خیرین'!D:D,Table1[[#This Row],[نام]],'لیست واریزی کل خیرین'!E:E,Table1[[#This Row],[نام خانوادگی]]) -> 2 | C34: بهنام | D34: بهرمن | E34: 1401/04/18 | F34: عفت هروی(بهرمن) | G34: تیر | H34: =IF(G34="","",VLOOKUP(G34,mah,2,0)) -> 4 | I34: 1401 | K34: 5000000
A35: ok | B35: =SUMIFS('لیست واریزی کل خیرین'!B:B,'لیست واریزی کل خیرین'!D:D,Table1[[#This Row],[نام]],'لیست واریزی کل خیرین'!E:E,Table1[[#This Row],[نام خانوادگی]]) -> 2 | C35: بهنام | D35: بهرمن | E35: 1401/04/25 | F35: عطیه نادری | G35: تیر | H35: =IF(G35="","",VLOOKUP(G35,mah,2,0)) -> 4 | I35: 1401 | K35: 15000000 | L35: واریز دوم
A36: ok | B36: =SUMIFS('لیست واریزی کل خیرین'!B:B,'لیست واریزی کل خیرین'!D:D,Table1[[#This Row],[نام]],'لیست واریزی کل خیرین'!E:E,Table1[[#This Row],[نام خانوادگی]]) -> 4 | C36: فرهنگ | D36: بهلول | E36: 1401/04/14 | F36: 6.219861e+15 | G36: تیر | H36: =IF(G36="","",VLOOKUP(G36,mah,2,0)) -> 4 | I36: 1401 | K36: 2000000
A37: ok | B37: =SUMIFS('لیست واریزی کل خیرین'!B:B,'لیست واریزی کل خیرین'!D:D,Table1[[#This Row],[نام]],'لیست واریزی کل خیرین'!E:E,Table1[[#This Row],[نام خانوادگی]]) -> 26 | C37: مهدی | D37: پرواز | E37: 1401/04/08 | F37: 6.0379918e+15 | G37: تیر | H37: =IF(G37="","",VLOOKUP(G37,mah,2,0)) -> 4 | I37: 1401 | K37: 10000000
A38: ok | B38: =SUMIFS('لیست واریزی کل خیرین'!B:B,'لیست واریزی کل خیرین'!D:D,Table1[[#This Row],[نام]],'لیست واریزی کل خیرین'!E:E,Table1[[#This Row],[نام خانوادگی]]) -> 25 | C38: محمد رضا | D38: پوررضایی | E38: 1401/04/07 | F38: 6.0379972e+15 | G38: تیر | H38: =IF(G38="","",VLOOKUP(G38,mah,2,0)) -> 4 | I38: 1401 | K38: 30000000
A39: ok | B39: =SUMIFS('لیست واریزی کل خیرین'!B:B,'لیست واریزی کل خیرین'!D:D,Table1[[#This Row],[نام]],'لیست واریزی کل خیرین'!E:E,Table1[[#This Row],[نام خانوادگی]]) -> 39 | C39: مهدی | D39: تولیت | E39: 1401/04/30 | F39: 6.0376976e+15 | G39: تیر | H39: =IF(G39="","",VLOOKUP(G39,mah,2,0)) -> 4 | I39: 1401 | K39: 16000000 | L39: اصل واریزی 3/2 میلیون بوده که برای مرداد و تیر لحاظ شده است
A40: ok | B40: =SUMIFS('لیست واریزی کل خیرین'!B:B,'لیست واریزی کل خیرین'!D:D,Table1[[#This Row],[نام]],'لیست واریزی کل خیرین'!E:E,Table1[[#This Row],[نام خانوادگی]]) -> 24 | D40: جعفری آزاد | E40: 1401/04/06 | F40: 5.0222913e+15 | G40: تیر | H40: =IF(G40="","",VLOOKUP(G40,mah,2,0)) -> 4 | I40: 1401 | K40: 5000000
...

Sheet لیست واریزی کل خیرین
F2: 1401 | G2: 1402 | J2: 1401 | K2: 1401 | L2: 1401 | M2: 1401 | N2: 1401 | O2: 1401 | P2: 1401 | Q2: 1401 | R2: 1401 | S2: 1401 | T2: 1401 | U2: 1401 | V2: 1402 | W2: 1402 | X2: 1402 | Y2: 1402 | Z2: 1402 | AA2: 1402 | AB2: 1402 | AC2: 1402 | AD2: 1402 | AE2: 1402 | AF2: 1402 | AG2: 1402
B3: کد | D3: نام | E3: نام خانوادگی | F3: کل واریزی 1401 | G3: کل واریزی 1402 | H3: کل واریزی | J3: فروردین | K3: اردیبهشت | L3: خرداد | M3: تیر | N3: مرداد | O3: شهریور | P3: مهر | Q3: آبان | R3: آذر | S3: دی | T3: بهمن | U3: اسفند | V3: فروردین | W3: اردیبهشت | X3: خرداد | Y3: تیر | Z3: مرداد | AA3: شهریور | AB3: مهر | AC3: آبان | AD3: آذر | AE3: دی | AF3: بهمن | AG3: اسفند
B4: 1 | C4: ماهیانه | D4: فرید | E4: برهان علمی | F4: =SUMIFS(Table1[مبلغ واریزی],Table1[ردیف],$B4,Table1[سال],F$2) -> 100000000 | G4: =SUMIFS(Table1[مبلغ واریزی],Table1[ردیف],$B4,Table1[سال],G$2) -> 120000000 | H4: =SUMIF('لیست واریزی ماهیانه'!B:B,'لیست واریزی کل خیرین'!$B4,'لیست واریزی ماهیانه'!K:K) -> 220000000 | J4: =SUMIFS('لیست واریزی ماهیانه'!$K:$K,'لیست واریزی ماهیانه'!$G:$G,'لیست واریزی کل خیرین'!J$3,'لیست واریزی ماهیانه'!$B:$B,'لیست واریزی کل خیرین'!$B:$B,'لیست واریزی ماهیانه'!$I:$I,J$2) -> 0 | K4: =SUMIFS('لیست واریزی ماهیانه'!$K:$K,'لیست واریزی ماهیانه'!$G:$G,'لیست واریزی کل خیرین'!K$3,'لیست واریزی ماهیانه'!$B:$B,'لیست واریزی کل خیرین'!$B:$B,'لیست واریزی ماهیانه'!$I:$I,K$2) -> 0 | L4: =SUMIFS('لیست واریزی ماهیانه'!$K:$K,'لیست واریزی ماهیانه'!$G:$G,'لیست واریزی کل خیرین'!L$3,'لیست واریزی ماهیانه'!$B:$B,'لیست واریزی کل خیرین'!$B:$B,'لیست واریزی ماهیانه'!$I:$I,L$2) -> 10000000 | M4: =SUMIFS('لیست واریزی ماهیانه'!$K:$K,'لیست واریزی ماهیانه'!$G:$G,'لیست واریزی کل خیرین'!M$3,'لیست واریزی ماهیانه'!$B:$B,'لیست واریزی کل خیرین'!$B:$B,'لیست واریزی ماهیانه'!$I:$I,M$2) -> 10000000 | N4: =SUMIFS('لیست واریزی ماهیانه'!$K:$K,'لیست واریزی ماهیانه'!$G:$G,'لیست واریزی کل خیرین'!N$3,'لیست واریزی ماهیانه'!$B:$B,'لیست واریزی کل خیرین'!$B:$B,'لیست واریزی ماهیانه'!$I:$I,N$2) -> 10000000 | O4: =SUMIFS('لیست واریزی ماهیانه'!$K:$K,'لیست واریزی ماهیانه'!$G:$G,'لیست واریزی کل خیرین'!O$3,'لیست واریزی ماهیانه'!$B:$B,'لیست واریزی کل خیرین'!$B:$B,'لیست واریزی ماهیانه'!$I:$I,O$2) -> 0 | P4: =SUMIFS('لیست واریزی ماهیانه'!$K:$K,'لیست واریزی ماهیانه'!$G:$G,'لیست واریزی کل خیرین'!P$3,'لیست واریزی ماهیانه'!$B:$B,'لیست واریزی کل خیرین'!$B:$B,'لیست واریزی ماهیانه'!$I:$I,P$2) -> 0 | Q4: =SUMIFS('لیست واریزی ماهیانه'!$K:$K,'لیست واریزی ماهیانه'!$G:$G,'لیست واریزی کل خیرین'!Q$3,'لیست واریزی ماهیانه'!$B:$B,'لیست واریزی کل خیرین'!$B:$B,'لیست واریزی ماهیانه'!$I:$I,Q$2) -> 11169500 | ... AG4: =SUMIFS('لیست واریزی ماهیانه'!$K:$K,'لیست واریزی ماهیانه'!$G:$G,'لیست واریزی کل خیرین'!AG$3,'لیست واریزی ماهیانه'!$B:$B,'لیست واریزی کل خیرین'!$B:$B,'لیست واریزی ماهیانه'!$I:$I,AG$2) -> 10000000
B5: 2 | C5: ماهیانه | D5: بهنام | E5: بهرمن | F5: =SUMIFS(Table1[مبلغ واریزی],Table1[ردیف],$B5,Table1[سال],F$2) -> 250000000 | G5: =SUMIFS(Table1[مبلغ واریزی],Table1[ردیف],$B5,Table1[سال],G$2) -> 100000000 | H5: =SUMIF('لیست واریزی ماهیانه'!B:B,'لیست واریزی کل خیرین'!$B5,'لیست واریزی ماهیانه'!K:K) -> 350000000 | J5: =SUMIFS('لیست واریزی ماهیانه'!$K:$K,'لیست واریزی ماهیانه'!$G:$G,'لیست واریزی کل خیرین'!J$3,'لیست واریزی ماهیانه'!$B:$B,'لیست واریزی کل خیرین'!$B:$B,'لیست واریزی ماهیانه'!$I:$I,J$2) -> 0 | K5: =SUMIFS('لیست واریزی ماهیانه'!$K:$K,'لیست واریزی ماهیانه'!$G:$G,'لیست واریزی کل خیرین'!K$3,'لیست واریزی ماهیانه'!$B:$B,'لیست واریزی کل خیرین'!$B:$B,'لیست واریزی ماهیانه'!$I:$I,K$2) -> 0 | L5: =SUMIFS('لیست واریزی ماهیانه'!$K:$K,'لیست واریزی ماهیانه'!$G:$G,'لیست واریزی کل خیرین'!L$3,'لیست واریزی ماهیانه'!$B:$B,'لیست واریزی کل خیرین'!$B:$B,'لیست واریزی ماهیانه'!$I:$I,L$2) -> 20000000 | M5: =SUMIFS('لیست واریزی ماهیانه'!$K:$K,'لیست واریزی ماهیانه'!$G:$G,'لیست واریزی کل خیرین'!M$3,'لیست واریزی ماهیانه'!$B:$B,'لیست واریزی کل خیرین'!$B:$B,'لیست واریزی ماهیانه'!$I:$I,M$2) -> 20000000 | N5: =SUMIFS('لیست واریزی ماهیانه'!$K:$K,'لیست واریزی ماهیانه'!$G:$G,'لیست واریزی کل خیرین'!N$3,'لیست واریزی ماهیانه'!$B:$B,'لیست واریزی کل خیرین'!$B:$B,'لیست واریزی ماهیانه'!$I:$I,N$2) -> 10000000 | O5: =SUMIFS('لیست واریزی ماهیانه'!$K:$K,'لیست واریزی ماهیانه'!$G:$G,'لیست واریزی کل خیرین'!O$3,'لیست واریزی ماهیانه'!$B:$B,'لیست واریزی کل خیرین'!$B:$B,'لیست واریزی ماهیانه'!$I:$I,O$2) -> 20000000 | P5: =SUMIFS('لیست واریزی ماهیانه'!$K:$K,'لیست واریزی ماهیانه'!$G:$G,'لیست واریزی کل خیرین'!P$3,'لیست واریزی ماهیانه'!$B:$B,'لیست واریزی کل خیرین'!$B:$B,'لیست واریزی ماهیانه'!$I:$I,P$2) -> 20000000 | Q5: =SUMIFS('لیست واریزی ماهیانه'!$K:$K,'لیست واریزی ماهیانه'!$G:$G,'لیست واریزی کل خیرین'!Q$3,'لیست واریزی ماهیانه'!$B:$B,'لیست واریزی کل خیرین'!$B:$B,'لیست واریزی ماهیانه'!$I:$I,Q$2) -> 20000000 | ... AG5: =SUMIFS('لیست واریزی ماهیانه'!$K:$K,'لیست واریزی ماهیانه'!$G:$G,'لیست واریزی کل خیرین'!AG$3,'لیست واریزی ماهیانه'!$B:$B,'لیست واریزی کل خیرین'!$B:$B,'لیست واریزی ماهیانه'!$I:$I,AG$2) -> 0
